<?xml version="1.0" ?>
<!--simple pbot-->

<robot name="PBot">
    <link name="base_link">
        <inertial>
            <origin xyz="0.0 0.0 0.0" rpy="0 0 0" />
            <mass value="1" />
            <inertia ixx="0.1" iyy="0.1" izz="0.1" ixy="0" ixz="0" iyz="0" />
        </inertial>
        <collision>
            <origin xyz="0.0 0.0 -1.0" rpy="0 0 0" />
            <geometry>
                <cylinder radius="0.25" length="1.0"/>
            </geometry>
        </collision>
        <visual>
            <origin xyz="0.0 0.0 -1.0" rpy="0 0 0" />
            <geometry>
                <cylinder radius="0.25" length="1.0"/>
            </geometry>
        </visual>
    </link>
    <link name="link0">
        <inertial>
            <origin xyz="0.0 0.0 0.0" rpy="0 0 0" />
            <mass value="1" />
            <inertia ixx="0.1" iyy="0.1" izz="0.1" ixy="0" ixz="0" iyz="0" />
        </inertial>
        <collision>
            <origin xyz="0.0 0.0 0.0" rpy="0 0 0" />
            <geometry>
                <sphere radius="0.1" />
            </geometry>
        </collision>
        <visual>
            <origin xyz="0.0 0.0 0.0" rpy="0 0 0" />
            <geometry>
                <sphere radius="0.1" />
            </geometry>
        </visual>
    </link>
    <link name="link1">
        <inertial>
            <origin xyz="0.0 0.0 0.0" rpy="0 0 0" />
            <mass value="1" />
            <inertia ixx="0.1" iyy="0.1" izz="0.1" ixy="0" ixz="0" iyz="0" />
        </inertial>
        <visual>
            <origin xyz="0.0 0.0 0.0" rpy="0 0 0" />
            <geometry>
                <sphere radius="0.1" />
            </geometry>
            <material name="material_blue">
                <color rgba="0.0 0.0 0.6 1.0" />
            </material>
        </visual>
    </link>
    
    <joint name="j0" type="prismatic">
        <parent link="base_link" />
        <child link="link0" />
        <origin xyz="0.000000 0.000000 2.000000" rpy="-0.000000 0.000000 -0.000000" />
        <axis xyz="0 0 1" />
        <limit lower="-2.967" upper="2.967" effort="176" velocity="1.7104" />
    </joint>
    <joint name="j1" type="fixed">
        <parent link="link0" />
        <child link="link1" />
        <origin xyz="0.000000 0.000000 0.200000" rpy="-0.000000 0.000000 -0.000000" />
        <limit lower="-2.967" upper="2.967" effort="176" velocity="1.7104" />
    </joint>
    
</robot>
