<?xml version="1.0" ?>
<!--simple pbot-->

<robot name="PBot">
    <link name="base_link">
        <inertial>
            <origin xyz="0.0 0.0 0.0" rpy="0 0 0" />
            <mass value="1" />
            <inertia ixx="0.1" iyy="0.1" izz="0.1" ixy="0" ixz="0" iyz="0" />
        </inertial>
    </link>
    <link name="link0">
        <inertial>
            <origin xyz="0.0 0.0 0.0" rpy="0 0 0" />
            <mass value="1" />
            <inertia ixx="0.1" iyy="0.1" izz="0.1" ixy="0" ixz="0" iyz="0" />
        </inertial>
        <visual>
            <origin xyz="0.0 0.0 0.0" rpy="0 0 0" />
            <geometry>
                <sphere radius="0.1" />
            </geometry>
        </visual>
    </link>

    <link name="sensor_link">
        <inertial>
            <origin xyz="0.0 0.0 0.0" rpy="0 0 0" />
            <mass value="0.01" />
            <inertia ixx="0.001" iyy="0.001" izz="0.001" ixy="0" ixz="0" iyz="0" />
        </inertial>
        <collision>
            <origin xyz="0.0 0.0 0.0" rpy="0 0 0" />
            <geometry>
                <box size="0.2 0.2 0.05" />
            </geometry>
        </collision>
        <visual>
            <origin xyz="0.0 0.0 0.0" rpy="0 0 0" />
            <geometry>
                <box size="0.2 0.2 0.05" />
            </geometry>
            <material name="custom">
                <color rgba="0.0 0.0 0.4 1.0" />
            </material>
        </visual>
    </link>
    
    <joint name="j0" type="prismatic">
        <parent link="base_link" />
        <child link="link0" />
        <origin xyz="0.000000 0.000000 1.000000" rpy="-0.000000 0.000000 -0.000000" />
        <axis xyz="0 0 1" />
        <limit lower="-2.967" upper="2.967" effort="176" velocity="1.7104" />
    </joint>
    <joint name="j_sensor" type="fixed">
        <parent link="link0" />
        <child link="sensor_link" />
        <origin xyz="0.000000 0.000000 -0.090000" rpy="0.000000 0.000000 -0.000000" />
        <limit lower="-2.967" upper="2.967" effort="176" velocity="1.7104" />
    </joint>


</robot>



